<?xml version="1.0" encoding="utf-8"?>
<!-- This URDF was automatically created by SolidWorks to URDF Exporter! Originally created by Stephen Brawner (brawner@gmail.com) 
     Commit Version: 1.6.0-1-g15f4949  Build Version: 1.6.7594.29634
     For more information, please see http://wiki.ros.org/sw_urdf_exporter -->
<robot
  name="fanuc_description">
  <link
    name="base_link">
    <inertial>
      <origin
        xyz="0.0026775 0.00013126 0.1402"
        rpy="0 0 0" />
      <mass
        value="23.654" />
      <inertia
        ixx="0.32988"
        ixy="0.0004327"
        ixz="0.0033897"
        iyy="0.33654"
        iyz="0.00021836"
        izz="0.30696" />
    </inertial>
    <visual>
      <origin
        xyz="0 0 0"
        rpy="0 0 0" />
      <geometry>
        <mesh
          filename="package://fanuc_description/meshes/base_link.STL" />
      </geometry>
      <material
        name="base_link_mat">
        <color
          rgba="0 0 0 1" />
      </material>
    </visual>
    <collision>
      <origin
        xyz="0 0 0"
        rpy="0 0 0" />
      <geometry>
        <mesh
          filename="package://fanuc_description/meshes/base_link.STL" />
      </geometry>
    </collision>
  </link>
  <link
    name="link_1">
    <inertial>
      <origin
        xyz="0.066637 0.01583 0.15136"
        rpy="0 0 0" />
      <mass
        value="21.047" />
      <inertia
        ixx="0.41047"
        ixy="0.0067561"
        ixz="-0.0723"
        iyy="0.35055"
        iyz="-0.030018"
        izz="0.43716" />
    </inertial>
    <visual>
      <origin
        xyz="0 0 0"
        rpy="0 0 0" />
      <geometry>
        <mesh
          filename="package://fanuc_description/meshes/link_1.STL" />
      </geometry>
      <material
        name="link_1_mat">
        <color
          rgba="0.9 0.8 0.2 1" />
      </material>
    </visual>
    <collision>
      <origin
        xyz="0 0 0"
        rpy="0 0 0" />
      <geometry>
        <mesh
          filename="package://fanuc_description/meshes/link_1.STL" />
      </geometry>
    </collision>
  </link>
  <joint
    name="J0"
    type="revolute">
    <origin
      xyz="0 0 0.3076"
      rpy="0 0 0" />
    <parent
      link="base_link" />
    <child
      link="link_1" />
    <axis
      xyz="0 0 1" />
    <limit
      lower="-2.9671"
      upper="2.9671"
      effort="12"
      velocity="3.4" />
    <dynamics
      damping="10"
      friction="50" />
  </joint>
  <link
    name="link_2">
    <inertial>
      <origin
        xyz="-4.7647E-05 -0.10746 0.39459"
        rpy="0 0 0" />
      <mass
        value="14.029" />
      <inertia
        ixx="0.92334"
        ixy="7.4339E-05"
        ixz="-7.8514E-05"
        iyy="0.93318"
        iyz="-0.0041433"
        izz="0.053319" />
    </inertial>
    <visual>
      <origin
        xyz="0 0 0"
        rpy="0 0 0" />
      <geometry>
        <mesh
          filename="package://fanuc_description/meshes/link_2.STL" />
      </geometry>
      <material
        name="link_2_mat">
        <color
          rgba="0.9 0.8 0.2 1" />
      </material>
    </visual>
    <collision>
      <origin
        xyz="0 0 0"
        rpy="0 0 0" />
      <geometry>
        <mesh
          filename="package://fanuc_description/meshes/link_2.STL" />
      </geometry>
    </collision>
  </link>
  <joint
    name="J1"
    type="revolute">
    <origin
      xyz="0.15 -0.062 0.2174"
      rpy="0 0 0" />
    <parent
      link="link_1" />
    <child
      link="link_2" />
    <axis
      xyz="0 1 0" />
    <limit
      lower="-2.2689"
      upper="2.2689"
      effort="12"
      velocity="3.05" />
    <dynamics
      damping="10"
      friction="50" />
  </joint>
  <link
    name="link_3">
    <inertial>
      <origin
        xyz="0.10039 0.043754 0.1067"
        rpy="0 0 0" />
      <mass
        value="13.287" />
      <inertia
        ixx="0.30219"
        ixy="0.01565"
        ixz="-0.064974"
        iyy="0.25299"
        iyz="-0.0090526"
        izz="0.23865" />
    </inertial>
    <visual>
      <origin
        xyz="0 0 0"
        rpy="0 0 0" />
      <geometry>
        <mesh
          filename="package://fanuc_description/meshes/link_3.STL" />
      </geometry>
      <material
        name="link_3_mat">
        <color
          rgba="0.9 0.8 0.2 1" />
      </material>
    </visual>
    <collision>
      <origin
        xyz="0 0 0"
        rpy="0 0 0" />
      <geometry>
        <mesh
          filename="package://fanuc_description/meshes/link_3.STL" />
      </geometry>
    </collision>
  </link>
  <joint
    name="J2"
    type="revolute">
    <origin
      xyz="0 0 0.79"
      rpy="0 0 0" />
    <parent
      link="link_2" />
    <child
      link="link_3" />
    <axis
      xyz="0 1 0" />
    <limit
      lower="-3.9968"
      upper="3.9968"
      effort="12"
      velocity="3.14" />
    <dynamics
      damping="10"
      friction="50" />
  </joint>
  <link
    name="link_4">
    <inertial>
      <origin
        xyz="0.29927 -0.05655 -3.6145E-05"
        rpy="0 0 0" />
      <mass
        value="7.7538" />
      <inertia
        ixx="0.024919"
        ixy="0.028523"
        ixz="5.9523E-05"
        iyy="0.2559"
        iyz="-1.2993E-05"
        izz="0.25507" />
    </inertial>
    <visual>
      <origin
        xyz="0 0 0"
        rpy="0 0 0" />
      <geometry>
        <mesh
          filename="package://fanuc_description/meshes/link_4.STL" />
      </geometry>
      <material
        name="link_4_mat">
        <color
          rgba="0.9 0.8 0.2 1" />
      </material>
    </visual>
    <collision>
      <origin
        xyz="0 0 0"
        rpy="0 0 0" />
      <geometry>
        <mesh
          filename="package://fanuc_description/meshes/link_4.STL" />
      </geometry>
    </collision>
  </link>
  <joint
    name="J3"
    type="revolute">
    <origin
      xyz="0.22329 0.062 0.25"
      rpy="0 0 0" />
    <parent
      link="link_3" />
    <child
      link="link_4" />
    <axis
      xyz="1 0 0" />
    <limit
      lower="-3.4907"
      upper="3.4907"
      effort="11.7"
      velocity="6.28" />
    <dynamics
      damping="10"
      friction="50" />
  </joint>
  <link
    name="link_5">
    <inertial>
      <origin
        xyz="0.030527 -0.021471 6.6749E-08"
        rpy="0 0 0" />
      <mass
        value="0.78107" />
      <inertia
        ixx="0.0017182"
        ixy="-0.00048263"
        ixz="-6.383E-10"
        iyy="0.0020734"
        iyz="-3.9859E-10"
        izz="0.0018545" />
    </inertial>
    <visual>
      <origin
        xyz="0 0 0"
        rpy="0 0 0" />
      <geometry>
        <mesh
          filename="package://fanuc_description/meshes/link_5.STL" />
      </geometry>
      <material
        name="link_5_mat">
        <color
          rgba="0.9 0.8 0.2 1" />
      </material>
    </visual>
    <collision>
      <origin
        xyz="0 0 0"
        rpy="0 0 0" />
      <geometry>
        <mesh
          filename="package://fanuc_description/meshes/link_5.STL" />
      </geometry>
    </collision>
  </link>
  <joint
    name="J4"
    type="revolute">
    <origin
      xyz="0.611708100522418 0 0"
      rpy="0 0 0" />
    <parent
      link="link_4" />
    <child
      link="link_5" />
    <axis
      xyz="0 1 0" />
    <limit
      lower="-3.1416"
      upper="3.1416"
      effort="11.7"
      velocity="6.28" />
    <dynamics
      damping="10"
      friction="50" />
  </joint>
  <link
    name="link_6">
    <inertial>
      <origin
        xyz="0.036896 -2.1336E-06 -1.0843E-05"
        rpy="0 0 0" />
      <mass
        value="0.050357" />
      <inertia
        ixx="3.8367E-05"
        ixy="2.7727E-09"
        ixz="1.4091E-08"
        iyy="3.5325E-05"
        iyz="2.9529E-09"
        izz="3.5339E-05" />
    </inertial>
    <visual>
      <origin
        xyz="0 0 0"
        rpy="0 0 0" />
      <geometry>
        <mesh
          filename="package://fanuc_description/meshes/link_6.STL" />
      </geometry>
      <material
        name="link_6_mat">
        <color
          rgba="0.3 0.1 0.3 1" />
      </material>
    </visual>
    <collision>
      <origin
        xyz="0 0 0"
        rpy="0 0 0" />
      <geometry>
        <mesh
          filename="package://fanuc_description/meshes/link_6.STL" />
      </geometry>
    </collision>
  </link>
  <joint
    name="J5"
    type="revolute">
    <origin
      xyz="0.0355 0 0"
      rpy="0 0 0" />
    <parent
      link="link_5" />
    <child
      link="link_6" />
    <axis
      xyz="1 0 0" />
    <limit
      lower="-7.8554"
      upper="7.854"
      effort="11.7"
      velocity="9.6" />
    <dynamics
      damping="10"
      friction="50" />
  </joint>
</robot>